Workbook

Sheet README
B2: Department of Computer Engineering
B3: Academic Year-2022-23 | I3: Semester- | K3: II | O3: Class:- FY | Q3: Div:-C,D,E
B4: Course- Applied Mathematics Name of Faculty: Ms. S.S.Patil
B6: PROJECT TITLE: Academic Performance & CO-PO Attainment Analysis Using Excel
B8: OBJECTIVE: Analyze academic assessment data and calculate course outcome attainment to support academic monitoring and continuous improvement.
B11: TOOLS: Microsoft Excel
B13: KEY ANALYSIS: • Assessment data analysis • Data validation • CO attainment calculation • CO-PO/PSO mapping • Target vs actual attainment • Internal and external assessment analysis • Dashboard reporting • Observation and action-taken analysis
B23: DATA PRIVACY: The public portfolio version uses anonymized/aggregated or synthetically recreated data. No personally identifiable student information is included.
B30: Programme Outcomes (POs)
A31: PO1 | B31: Basic and Discipline specific knowledge: Apply knowledge of basic mathematics, science and engineering fundamentals and engineering specialization to solve the engineering problems. Basic and Discipline specific knowledge: Apply knowledge of basic mathematics, science and engineering fundamentals and engineering specialization to solve the engineering problems. Basic and Discipline specific knowledge: Apply knowledge of basic mathematics, science and engineering fundamentals and engineering specialization to solve the engineering problems.
A32: PO2 | B32: Problem analysis: Identify and analyse well-defined engineering problems using codified standard methods.
A33: PO3 | B33: Design/ development of solutions: Design solutions for well-defined technical problems and assist with the design of systems components or processes to meet specified needs.
A34: PO4 | B34: Engineering Tools, Experimentation and Testing: Apply modern engineering tools and appropriate technique to conduct standard tests and measurements.
A35: PO5 | B35: Engineering practices for society, sustainability and environment: Apply appropriate technology in context of society, sustainability, environment and ethical practices.
A36: PO6 | B36: Project Management: Use engineering management principles individually, as a team member or a leader to manage projects and effectively communicate about well-defined engineering activities.
A37: PO7 | B37: Life-long learning: Ability to analyse individual needs and engage in updating in the context of technological changes.
B39: Programme Specific Outcomes (PSOs)
A40: PSO1 | B40: Computer Software and Hardware Usage: Use state- of- the- art of technologies for opeartion and application of computer software and hardware .
A41: PSO2 | B41: Computer Engineering Maintenance: Maintain Computer Enginnering related software and hardware systems.

Sheet Teaching and Evaluation Scheme
B3: Department of Computer Engineering
B4: Academic Year-2022-23
B6: F.Y. Diploma (Computer Engineering) Semester-II
B7: Course Name:-Applied Mathematics (22224)
B8: Course Code:-22224
B9: Teaching Scheme: 4Hrs/ Week Tutorial : 2 Hrs/ Week
B10: Examination Scheme: TH-PA-30 Marks TH-ESE-70Marks
B12: CO number and CO statements
B13: At the end of course, students will able to
B14: 22224.1 - Calculate the equation of tangent ,maxima,minima,radius of curvature by differentiation
B15: 22224.2 - Solve the given problems of integration using suitable method
B16: 22224.3 - Apply the concept of integration to find area and volume
... B18: 22224.5 - Apply numerical methods to solve program specific problems
D19: =CONCATENATE(A19,B19)

Sheet CO_PO_Matrix
B4: Course: Applied Mathematics Course Code:- 22224 (Sem II 2022-23), CO-PO Mapping Justification
E8: CO-PO Target Matrix
B10: CO | C10: PO | D10: 1 | E10: 2 | F10: 3 | G10: 4 | H10: 5 | I10: 6 | J10: 7 | K10: PSO1 | L10: PSO2 | T10: Contact hours | X10: Assessment Tools | Z10: Assessment Types
B11: 22224.1 | D11: © | E11: © | F11: © | G11: © | I11: © | J11: © | K11: © | T11: <5% No mapping | X11: 0 | Y11: No mapping | Z11: 0 | AA11: No mapping
B12: 22224.2 | D12: © | E12: © | H12: © | J12: © | K12: © | T12: Level1- 5 To 15% | X12: 1 to 2 | Y12: 1 | Z12: 1 | AA12: 1
B13: 22224.3 | D13: © | E13: © | H13: © | J13: © | K13: © | T13: level2- Above 15 To 25% | X13: 3 | Y13: 2 | Z13: 2 | AA13: 2
B14: 22224.4 | D14: © | E14: © | F14: © | G14: © | H14: © | I14: © | J14: © | K14: © | T14: Level 3- >25% | X14: 4or more | Y14: 3 | Z14: above 3 | AA14: 3
B15: 22224.5 | D15: © | E15: © | F15: © | G15: © | H15: © | I15: © | J15: © | K15: ©
T17: Assessment Tools = CT ,CES,MPR | Z17: Assessment type = TH-ESE
A18: PO1 | B18: Basic and Discipline specific knowledge
S19: Lec: 4hrs per week | U19: Tutorial: 02 hrs per week | AA19: Total hrs:64+32=96
A20: BTL | B20: CO | C20: Course Coutcome | K20: Contact Hours | L20: Level | M20: Assessment Tools | N20: Level | O20: Assessment Type | P20: Level | Q20: PO1
A21: L3 | B21: 22224.1 | C21: Calculate the equation of tangent ,maxima,minima,radius of curvature by differentiation | K21: 0.3125 | L21: 3 | M21: 3 | N21: 2 | O21: 1 | P21: 1 | Q21: =AVERAGE(L21,N21,P21) -> 2 | S21: For CO 22224.1 Total lec 20+ Tut=10hrs, Total =30 Contact hrs in %=(30/96)*100=31.25%
A22: L3 | B22: 22224.2 | C22: Solve the given problems of integration using suitable method | K22: 0.2083 | L22: 2 | M22: 3 | N22: 2 | O22: 1 | P22: 1 | Q22: =AVERAGE(L22,N22,P22) -> 1.6666667 | S22: For CO 22224.2 Total lec 14 + Tut=06hrs, Total=20 Contact hrs in %=(24/96)*100=20.83%
A23: L3 | B23: 22224.3 | C23: Apply the concept of integration to find area and volume | K23: 0.1458 | L23: 1 | M23: 3 | N23: 2 | O23: 1 | P23: 1 | Q23: =AVERAGE(L23,N23,P23) -> 1.3333333 | S23: For CO 22224.3 Total lec 10 + Tut=04 hrs, Total=14 Contact hrs in %=(12/96)*100=14.58%
A24: L3 | B24: 22224.4 | C24: Solve the differential equation of first order and firs degree using suitable methods | K24: 0.1458 | L24: 1 | M24: 3 | N24: 2 | O24: 1 | P24: 1 | Q24: =AVERAGE(L24,N24,P24) -> 1.3333333 | S24: For CO 22224.4 Total lec 08 + Tut=06hrs, Total=14 Contact hrs in %=(14/96)*100=14.58%
A25: L3 | B25: 22224.5 | C25: Apply numerical methods to solve program specific problems | K25: 0.1875 | L25: 2 | M25: 3 | N25: 2 | O25: 1 | P25: 1 | Q25: =AVERAGE(L25,N25,P25) -> 1.6666667 | S25: For CO 22224.5 Total lec 12 + Tut=06hrs, Total=18 Contact hrs in %=(16/96)*100=18.75%
A27: PO2 | B27: Problem analysis
A29: BTL | B29: CO | C29: Course Coutcome | K29: Contact Hours | L29: Level | M29: Assessment Tools | N29: Level | O29: Assessment Type | P29: Level | Q29: PO2
A30: L3 | B30: 22224.1 | C30: Calculate the equation of tangent ,maxima,minima,radius of curvature by differentiation | K30: 0.3125 | L30: 3 | M30: 3 | N30: 2 | O30: 1 | P30: 1 | Q30: =AVERAGE(L30,N30,P30) -> 2
A31: L3 | B31: 22224.2 | C31: Solve the given problems of integration using suitable method | K31: 0.2083 | L31: 2 | M31: 3 | N31: 2 | O31: 1 | P31: 1 | Q31: =AVERAGE(L31,N31,P31) -> 1.6666667
A32: L3 | B32: 22224.3 | C32: Apply the concept of integration to find area and volume | K32: 0.1458 | L32: 1 | M32: 3 | N32: 2 | O32: 1 | P32: 1 | Q32: =AVERAGE(L32,N32,P32) -> 1.3333333
A33: L3 | B33: 22224.4 | C33: Solve the differential equation of first order and firs degree using suitable methods | K33: 0.1458 | L33: 1 | M33: 3 | N33: 2 | O33: 1 | P33: 1 | Q33: =AVERAGE(L33,N33,P33) -> 1.3333333
A34: L3 | B34: 22224.5 | C34: Apply numerical methods to solve program specific problems | K34: 0.1875 | L34: 2 | M34: 3 | N34: 2 | O34: 1 | P34: 1 | Q34: =AVERAGE(L34,N34,P34) -> 1.6666667
A36: PO3 Design/ development of solutions
A38: BTL | B38: Course Coutcome (Engineering Physics Theory) | K38: Contact Hours | L38: Level | M38: Assessment Tools | N38: Level | O38: Assessment Type | P38: Level | Q38: PO3
A39: L3 | B39: 22224.1 | C39: Calculate the equation of tangent ,maxima,minima,radius of curvature by differentiation | K39: 0.3125 | L39: 3 | M39: 3 | N39: 2 | O39: 1 | P39: 1 | Q39: =AVERAGE(L39,N39,P39) -> 2
A40: L3 | B40: 22224.2 | C40: Solve the given problems of integration using suitable method
A41: L3 | B41: 22224.3 | C41: Apply the concept of integration to find area and volume
A42: L3 | B42: 22224.4 | C42: Solve the differential equation of first order and firs degree using suitable methods | K42: 0.1458 | L42: 1 | M42: 3 | N42: 2 | O42: 1 | P42: 1 | Q42: =AVERAGE(L42,N42,P42) -> 1.3333333
A43: L3 | B43: 22224.5 | C43: Apply numerical methods to solve program specific problems | K43: 0.1875 | L43: 2 | M43: 3 | N43: 2 | O43: 1 | P43: 1 | Q43: =AVERAGE(L43,N43,P43) -> 1.6666667
A45: PO4 Engineering Tools, Experimentation and Testing
A47: BTL | B47: Course Coutcome (Engineering Physics Theory) | K47: Contact Hours | L47: Level | M47: Assessment Tools | N47: Level | O47: Assessment Type | P47: Level | Q47: PO4
A48: L3 | B48: 22224.1 | C48: Calculate the equation of tangent ,maxima,minima,radius of curvature by differentiation | K48: 0.3125 | L48: 3 | M48: 3 | N48: 2 | O48: 1 | P48: 1 | Q48: =AVERAGE(L48,N48,P48) -> 2
A49: L3 | B49: 22224.2 | C49: Solve the given problems of integration using suitable method
A50: L3 | B50: 22224.3 | C50: Apply the concept of integration to find area and volume
A51: L3 | B51: 22224.4 | C51: Solve the differential equation of first order and firs degree using suitable methods | K51: 0.1458 | L51: 1 | M51: 3 | N51: 2 | O51: 1 | P51: 1 | Q51: =AVERAGE(L51,N51,P51) -> 1.3333333
A52: L3 | B52: 22224.5 | C52: Apply numerical methods to solve program specific problems | K52: 0.1875 | L52: 2 | M52: 3 | N52: 2 | O52: 1 | P52: 1 | Q52: =AVERAGE(L52,N52,P52) -> 1.6666667
A54: PO5 Engineering practices for society, sustainability and environment
A56: BTL | B56: Course Coutcome (Engineering Physics Theory) | K56: Contact Hours | L56: Level | M56: Assessment Tools | N56: Level | O56: Assessment Type | P56: Level | Q56: PO5
...

Sheet CO_PO_Mapping
U1: Dr. D. Y. PATIL POLYTECHNIC, KOLHAPUR
U2: Department of ------------------ Engineering
A3: A.Y | B3: 2022-23 | D3: Class and Div | F3: FY | G3: C,D,E | H3: Faculty | I3: Ms. S.S.Patil | U3: A.Y | V3: 2023-24 | AB3: Class and Div | AG3: Faculty
A4: Course code | C4: 22224 | D4: Course | E4: AMI | U4: course code | AB4: Course
A5: CO-PO/PSO Mapping | U5: CO-PO/PSO Mapping
M6: Final Attinment= ((0.6 of IAA)+(0.4 EA)) | U6: CO | V6: PO | AJ6: PSO
A7: CO | B7: PO | I7: PSO | V7: 1 | W7: 2 | X7: 3 | AA7: 4 | AB7: 5 | AC7: 6 | AD7: 7 | AJ7: 1 | AK7: 2
B8: 1 | C8: 2 | D8: 3 | E8: 4 | F8: 5 | G8: 6 | H8: 7 | I8: 1 | J8: 2 | M8: Tool | N8: Detail | O8: Weightages | P8: Criteria | U8: C403.1 | AP8: Tool | AQ8: Detail | AR8: Weightages | AS8: Criteria
A9: 22224.1 | B9: 2 | C9: 2 | D9: 2 | E9: 2 | G9: 2 | H9: 1 | I9: 1 | M9: CT1 | N9: Class Test 1 | O9: 0.4 | P9: Internal Assessment(IAA) | U9: C403.2 | AP9: MT | AQ9: Mid Term Test | AR9: 0.15 | AS9: Internal Assessment(IA)
A10: 22224.2 | B10: 1.6666667 | C10: 1.6666667 | F10: 1.6666667 | H10: 1 | I10: 1 | M10: CT2 | N10: Class Test 2 | O10: 0.4 | U10: C403.3 | AP10: ET | AQ10: End Term Test | AR10: 0.15
A11: 22224.3 | B11: 1.3333333 | C11: 1.3333333 | F11: 1.3333333 | H11: 1 | I11: 1 | M11: MP | N11: Microproject | O11: 0.1 | U11: C403.4 | AP11: TW | AQ11: Termwork | AR11: 0.25
A12: 22224.4 | B12: 1.3333333 | C12: 1.3333333 | D12: 1.3333333 | E12: 1.3333333 | F12: 1.3333333 | G12: 1.3333333 | H12: 1 | I12: 1 | M12: CES | N12: Course Exit Survey | O12: 0.1 | U12: C403.5 | AP12: CE | AQ12: Course Exit Survey | AR12: 0.05
A13: 22224.5 | B13: 1.6666667 | C13: 1.6666667 | D13: 1.6666667 | E13: 1.6666667 | F13: 1.6666667 | G13: 1.3333333 | H13: 1 | I13: 1 | U13: C403.6
M14: ESE-TH | N14: End Sem. Exam | O14: 1 | P14: External Assessment(EAA) | U14: =V4 -> 0 | V14: =IF(SUM(V8:V13)=0,"-",AVERAGE(V8:V13)) -> - | W14: =IF(SUM(W8:W13)=0,"-",AVERAGE(W8:W13)) -> - | X14: =IF(SUM(X8:X13)=0,"-",AVERAGE(X8:X13)) -> - | AA14: =IF(SUM(AA8:AA13)=0,"-",AVERAGE(AA8:AA13)) -> - | AB14: =IF(SUM(AB8:AB13)=0,"-",AVERAGE(AB8:AB13)) -> - | AC14: =IF(SUM(AC8:AC13)=0,"-",AVERAGE(AC8:AC13)) -> - | AD14: =IF(SUM(AD8:AD13)=0,"-",AVERAGE(AD8:AD13)) -> - | AE14: =IF(SUM(AE8:AE13)=0,"-",AVERAGE(AE8:AE13)) -> - | AF14: =IF(SUM(AF8:AF13)=0,"-",AVERAGE(AF8:AF13)) -> - | AG14: =IF(SUM(AG8:AG13)=0,"-",AVERAGE(AG8:AG13)) -> - | AH14: =IF(SUM(AH8:AH13)=0,"-",AVERAGE(AH8:AH13)) -> - | ... AK14: =IF(SUM(AK8:AK13)=0,"-",AVERAGE(AK8:AK13)) -> - | AP14: ESE | AQ14: End Sem. Exam | AR14: 0.4 | AS14: External Assessment(EA)
B15: =IF(SUM(B9:B13)=0,"-",AVERAGE(B9:B13)) -> 1.6 | C15: =IF(SUM(C9:C13)=0,"-",AVERAGE(C9:C13)) -> 1.6 | D15: =IF(SUM(D9:D13)=0,"-",AVERAGE(D9:D13)) -> 1.6666667 | E15: =IF(SUM(E9:E13)=0,"-",AVERAGE(E9:E13)) -> 1.6666667 | F15: =IF(SUM(F9:F13)=0,"-",AVERAGE(F9:F13)) -> 1.5 | G15: =IF(SUM(G9:G13)=0,"-",AVERAGE(G9:G13)) -> 1.5555556 | H15: =IF(SUM(H9:H13)=0,"-",AVERAGE(H9:H13)) -> 1 | I15: =IF(SUM(I9:I13)=0,"-",AVERAGE(I9:I13)) -> 1 | M15: ESE-PR | U15: CO Assessment tools | AP15: OE | AQ15: Oral Exam | AR15: 0
A16: CO Assessment tools | U16: CO | V16: INTERNAL | AH16: 60 | AI16: EXTERNAL | AL16: 40 | AM16: TOTAL
V17: Direct (based on marks) | AA17: INDIRECT (based on rubric) | AI17: Equal weight to all CO
A18: CO | B18: INTERNAL | G18: EXTERNAL | K18: TOTAL | M18: Sr. No. | N18: Academic Year | O18: % Result | P18: Avg. Marks | Q18: Average Result | R18: Average Marks | AP18: Sr. No. | AQ18: Academic Year | AR18: % Result | AS18: Avg. Marks | AT18: Average Result | AU18: Average Marks
B19: Direct (based on marks) | G19: Equal weight to all CO | M19: 1 | N19: 2021-22 | O19: 45.93 | P19: 41.718519 | V19: CT1 | W19: CT2 | X19: MP | Y19: TW | Z19: CES | AG19: TW | AH19: CE | AI19: UE | AJ19: OE | AP19: 1 | AQ19: 2021-22 | AR19: 100 | AS19: 83.32 | AT19: 93.35 | AU19: 72.8
B20: CT1 | C20: CT2 | D20: MP | F20: CES | G20: ESE-TH | M20: 2 | N20: 2020-21 | O20: 88.392857 | P20: 54.357143 | Q20: =AVERAGE(O19:O20:O21) -> 78.107619 | R20: =AVERAGE(P19:P20:P21) -> 55.87261 | U20: =U9 -> C403.2 | V20: Y | AG20: Y | AH20: Y | AI20: Y | AM20: 100 | AP20: 3 | AQ20: 2019-20 | AR20: 80.07 | AS20: 40
A21: 22224.1 | B21: Y | D21: Y | F21: Y | G21: Y | K21: 100 | M21: 3 | N21: 2019-20 | O21: 100 | P21: 71.542169 | U21: =U10 -> C403.3 | V21: Y | AG21: Y | AH21: Y | AI21: Y | AM21: 100
A22: 22224.2 | C22: Y | D22: Y | F22: Y | G22: Y | K22: 100 | U22: =U11 -> C403.4 | W22: Y | AG22: Y | AH22: Y | AI22: Y | AM22: 100
A23: 22224.3 | C23: Y | D23: Y | F23: Y | G23: Y | K23: 100 | U23: =U12 -> C403.5 | W23: Y | AG23: Y | AH23: Y | AI23: Y | AM23: 100
A24: 22224.4 | C24: Y | D24: Y | F24: Y | G24: Y | K24: 100 | U24: =U13 -> C403.6 | W24: Y | AG24: Y | AH24: Y | AI24: Y | AM24: 100
A25: 22224.5 | B25: Y | D25: Y | F25: Y | G25: Y | K25: 100
U26: Attainment levels | AF26: 1. In academic year 2020-21, 2021-22 the average marks of each student were drastically increased due to online mode final university examination.
U27: Level 1 | V27: 0.4 | W27: students will score more than | AC27: 0.45 | AD27: Marks
A28: Attainment levels | L28: Remark for Threshold / Benchmark setting- because of online examination in AY 2021-2022 and 2020-2021,result shows | U28: Level 2 | V28: 0.5 | W28: students will score more than | AC28: 0.45 | AD28: Marks | AF28: 2. Similarly the average marks for academic year 2019-20 is 40%. Therefore, this academic year the target for this course is set to 45%.
A29: Level 1 | B29: 0.4 | C29: students will score more than | I29: 0.5 | J29: Marks | U29: Level 3 | V29: 0.6 | W29: students will score more than | AC29: 0.45 | AD29: Marks
A30: Level 2 | B30: 0.5 | C30: students will score more than | I30: 0.5 | J30: Marks
A31: Level 3 | B31: 0.6 | C31: students will score more than | I31: 0.5 | J31: Marks
U32: CO | V32: Statements | AL32: BTL
A33: CO No. | B33: CO-Statements | I33: BTL | U33: =#REF! -> #REF! | V33: Elaborate the fundamental concepts of Finite Element method. | AL33: L2-Understand
A34: 22224.1 | B34: Calculate the equation of tangent ,maxima,minima,radius of curvature by differentiation | I34: L1,L2,L3 | U34: =U20 -> C403.2 | V34: Understand the key concepts like Shape function, element stiffness and boundary conditions by finite element formulations for 1D problem. | AL34: L3-Apply,L4- Analyze
A35: 22224.2 | B35: Solve the given problems of integration using suitable method | I35: L1,L2,L3 | U35: =U21 -> C403.3 | V35: Apply the finite element formulations for two dimensional problems using constant strain triangle. | AL35: L3-Apply,L4- Analyze
A36: 22224.3 | B36: Apply the concept of integration to find area and volume | I36: L1,L2,L3 | U36: =U22 -> C403.4 | V36: Demonstrate the modeling aspects of axisymmetric solids subjected to axisymmetric loading. | AL36: L3-Apply,L4- Analyze
A37: 22224.4 | B37: Solve the differential equation of first order and firs degree using suitable methods | I37: L1,L2,L3 | U37: =U23 -> C403.5 | V37: Apply the finite element formulations for Planer Trusses using 1D element. | AL37: L3-Apply,L4- Analyze
A38: 22224.5 | B38: Apply numerical methods to solve program specific problems | I38: L1,L2,L3 | U38: C403.6 | V38: Solve Scalar field problems by Finite element formulation. | AL38: L3-Apply,L4- Analyze
U45: Course Incharge | AF45: Program Coordinator | AQ45: H.o.D.

Sheet Rubrics
A2: Rubric for Termwork out of 25 Marks
A4: Criteria | B4: Performance Levels
B5: 13-15 marks | C5: 09-12 marks | D5: 04-08 marks | E5: 01-03 mark
A6: Lab Performance | B6: ü Able to understand and perform the analysis using the software. | C6: ü Partly able to understandand perform the analysis using the software. | D6: ü Rarely able to give contribution during lab performance. | E6: ü Never able to contribute for lab Performances.
A7: (15 Marks) | B7: ü Able to understand theoretical concept related to the problem statement. | C7: ü Partly able to understand theoretical concept related to the problem statement. | D7: ü Not able to complete assignment / write up submission within stipulated time. | E7: ü Require instructor help to write assignment/ journal
B8: ü Able to complete and submit assignment/journal write up within stipulated time. | C8: ü The assignment / Write up submission is not within stipulated time. | E8: ü Not able to complete assignment till final deadline of submission.
B9: 07-10 marks | C9: 05-06 marks | D9: 02-04 marks | E9: 01 mark
A10: Oral | B10: ü Able to give all answers to questions confidently. | C10: ü Able to ask and Clear Doubts. | D10: ü Incorrect answers to questions and Confused. | E10: ü Lack of knowledge of relevant questions
A11: (10 Marks) | B11: ü Able to interpret proper data to reach conclusion | C11: ü Partially give answers to questions and | D11: ü Incorrect interpretation of data to reach conclusion. | E11: ü Lack of interpretation of data
C12: ü Partially able to interpret data to reach conclusion. | E12: ü Don’t understand questions properly
A14: Rubric for PO5 Assessment
A15: Category No | B15: Category | C15: Level of Performance
C16: 4 to 5 | D16: 2 to 3 | E16: 1-0
A17: 1 | B17: Apply FE software to solve the problem | C17: 1.fully able to apply the software to solve the problem and able to explain. 2.Able to explain interpretation of results. | D17: 1.Partially able to apply the software to solve the problem andpartially able to explain 2.Partially able to explain interpretation of results. | E17: 1.unable to apply the software to solve the problem and unable to explain 2.unble to explain interpretation of results.
A20: Rubric for PO6 Assessment
A21: Category No | B21: Category | C21: Level of Performance
C22: 4 to 5 | D22: 2 to 3 | E22: 1-0
A23: 1 | B23: Able to apply resoning to assess safety of the components. | C23: 1.fully able to apply resoning to assess safety of the components. 2.Able to explain interpretation of results. | D23: 1.Partially able to resoning to assess safety of the components. 2.Partially able to explain interpretation of results. | E23: 1.unable to apply resoning to assess safety of the components. 2.unble to explain interpretation of results.
A25: Rubric for PO9 Assessment
A27: Category No | B27: Category | C27: Level of Performance
C28: 4 to 5 | D28: 2 to 3 | E28: 1-0
A29: 1 | B29: Group Leader | C29: Seeks opportunities to lead; leading is attentive to each member | D29: Will take lead if group insists; not good at being attentive to each member | E29: Resists taking on leadership role; in leading allows uneven contributions
A30: 2 | B30: Contribution | C30: Always contributes ; quality of contributions is exceptional | D30: Sometimes contributes; quality of contributions is fair | E30: Rarely contributes; contributions are often peripheral or irrelevant; frequently misses team sessions
A31: 3 | B31: Cooperation | C31: Always cooperative with all members, support good initiatives | D31: cooperative with members, but sometimes argue | E31: cooperative with few members, and argue most of time
A33: Rubric for PO10 Assessment
A34: Category No | B34: Category | C34: Level of Performance
C35: 4 to 5 | D35: 2 to 3 | E35: 1-0
A36: 1 | B36: Oral Communication ,Delivery & Speaking Skills | C36: Clear voice and correct pronunciation of terms. Good eye contact. | D36: Most words pronounced correctly. Some eye contact, | E36: Occasional mispronunciation of terms. Little eye contact, only littleexpression.
A37: 2 | B37: Written Communication Organization & Style | C37: presented in a logical, interesting way, which is easy to follow. Purpose is clearly stated and explains the structure of work. | D37: Information is presented in a logical manner, which is easily followed. Purpose of work is clearly stated and assists the structure of work . | E37: Work is hard to follow as there is very little continuity. Purpose of work is stated, but does not assist in following work.
A38: 3 | B38: Written Communication Spelling & Grammar | C38: Negligible misspelling sand/or grammatical errors. | D38: Minor misspellings and/or grammatical errors. | E38: Several spelling and grammatical errors.

Sheet RAW
A2: Course | B2: =CONCATENATE(CO_PO_Mapping!V4,"-",CO_PO_Mapping!AD4) -> -
A3: Assessment Tools | B3: MT | E3: ET | H3: CE | N3: UE | O3: TW
A4: CO Mapped | B4: C403.1 | C4: C403.2 | D4: C403.3 | E4: C403.4 | F4: C403.5 | G4: C403.6 | H4: =CO_PO_Mapping!#REF! -> #REF! | I4: =CO_PO_Mapping!U20 -> C403.2 | J4: =CO_PO_Mapping!U21 -> C403.3 | K4: =CO_PO_Mapping!U22 -> C403.4 | L4: =CO_PO_Mapping!U23 -> C403.5 | M4: C403.6 | N4: ALL CO | O4: ALL CO
A5: Maximum marks | B5: 8 | C5: 18 | D5: 4 | E5: 8 | F5: 10 | G5: 12 | H5: 5 | I5: 5 | J5: 5 | K5: 5 | L5: 5 | M5: 5 | N5: 70 | O5: 25
A6: TARGET | B6: 0.45 | C6: 0.45 | D6: 0.45 | E6: 0.45 | F6: 0.45 | G6: 0.45 | H6: 0.45 | I6: 0.45 | J6: 0.45 | K6: 0.45 | L6: 0.45 | M6: 0.45 | N6: 0.45 | O6: 0.45
A7: Target(threshold) marks | B7: =B6*B5 -> 3.6 | C7: =C6*C5 -> 8.1 | D7: =D6*D5 -> 1.8 | E7: =E6*E5 -> 3.6 | F7: =F6*F5 -> 4.5 | G7: =G6*G5 -> 5.4 | H7: =H6*H5 -> 2.25 | I7: =I6*I5 -> 2.25 | ... O7: =O6*O5 -> 11.25
A8: Final target | B8: 4 | C8: 8 | D8: 2 | E8: 4 | F8: 4 | G8: 5 | H8: =MAX(H7:H7)-0.00001 -> 2.24999 | I8: =MAX(I7:I7)-0.00001 -> 2.24999 | J8: =MAX(J7:J7)-0.00001 -> 2.24999 | K8: =MAX(K7:K7)-0.00001 -> 2.24999 | L8: =MAX(L7:L7)-0.00001 -> 2.24999 | M8: =MAX(M7:M7)-0.00001 -> 2.24999 | N8: =MAX(N7:N7)-0.00001 -> 31.49999 | O8: =MAX(O7:O7)-0.00001 -> 11.24999
A9: No of Students appered for CO | B9: =COUNT(B13:B87) -> 75 | C9: =COUNT(C13:C87) -> 75 | D9: =COUNT(D13:D87) -> 51 | E9: =COUNT(E13:E87) -> 32 | F9: =COUNT(F13:F87) -> 65 | G9: =COUNT(G13:G87) -> 40 | H9: =COUNT(H13:H87) -> 62 | I9: =COUNT(I13:I87) -> 62 | ... O9: =COUNT(O13:O87) -> 75
A10: No. of Students > target | B10: =COUNTIF(B13:B87,">=4") -> 13 | C10: =COUNTIF(C13:C87,">=8") -> 31 | D10: =COUNTIF(D13:D87,">=2") -> 43 | E10: =COUNTIF(E13:E87,">=4") -> 23 | F10: =COUNTIF(F13:F87,">=4") -> 50 | G10: =COUNTIF(G13:G87,">=5") -> 17 | H10: =COUNTIF(H13:H87,">=2") -> 62 | I10: =COUNTIF(I13:I87,">=2") -> 62 | J10: =COUNTIF(J13:J87,">=2") -> 62 | K10: =COUNTIF(K13:K87,">=2") -> 62 | L10: =COUNTIF(L13:L87,">=2") -> 62 | M10: =COUNTIF(M13:M87,">=2") -> 62 | N10: =COUNTIF(N13:N87,">=31") -> 30 | O10: =COUNTIF(O13:O87,">=11") -> 75
A11: % Students > target | B11: =B10/B9 -> 0.17333333 | C11: =C10/C9 -> 0.41333333 | D11: =D10/D9 -> 0.84313725 | E11: =E10/E9 -> 0.71875 | F11: =F10/F9 -> 0.76923077 | G11: =G10/G9 -> 0.425 | H11: =H10/H9 -> 1 | I11: =I10/I9 -> 1 | ... O11: =O10/O9 -> 1
A12: Attainement | B12: 0 | C12: 1 | D12: 3 | E12: 3 | F12: 3 | G12: 1 | H12: 3 | I12: 3 | J12: 3 | K12: 3 | L12: 3 | M12: 3 | N12: 1 | O12: 3
A13: 1 | B13: 0 | C13: 5 | D13: 2 | E13: 8 | F13: 4 | H13: 5 | I13: 4 | J13: 4 | K13: 5 | L13: 5 | M13: 5 | N13: 38 | O13: 19
A14: 2 | B14: 0 | C14: 5 | D14: 4 | E14: 8 | F14: 4 | H14: 5 | I14: 4 | J14: 4 | K14: 5 | L14: 5 | M14: 5 | N14: 32 | O14: 18
A15: 3 | B15: 0 | C15: 10 | D15: 4 | E15: 8 | F15: 4 | H15: 5 | I15: 4 | J15: 5 | K15: 4 | L15: 5 | M15: 5 | N15: 28 | O15: 22
A16: 4 | B16: 0 | C16: 10 | D16: 4 | E16: 4 | F16: 4 | H16: 5 | I16: 5 | J16: 5 | K16: 5 | L16: 5 | M16: 4 | N16: 29 | O16: 21
A17: 5 | B17: 3 | C17: 10 | E17: 8 | F17: 4 | H17: 5 | I17: 5 | J17: 5 | K17: 5 | L17: 5 | M17: 5 | N17: 32 | O17: 22
A18: 6 | B18: 0 | C18: 0 | D18: 4 | F18: 10 | G18: 0 | H18: 5 | I18: 5 | J18: 5 | K18: 5 | L18: 5 | M18: 5 | N18: 38 | O18: 23
A19: 7 | B19: 0 | C19: 6 | D19: 2 | F19: 4 | G19: 2 | H19: 5 | I19: 4 | J19: 4 | K19: 5 | L19: 5 | M19: 5 | N19: 30 | O19: 22
A20: 8 | B20: 0 | C20: 6 | D20: 4 | E20: 8 | F20: 4 | G20: 2 | N20: 37 | O20: 22
A21: 9 | B21: 0 | C21: 6 | D21: 2 | F21: 2 | H21: 5 | I21: 5 | J21: 5 | K21: 4 | L21: 5 | M21: 4 | N21: 15 | O21: 14
A22: 10 | B22: 0 | C22: 6 | F22: 6 | H22: 5 | I22: 5 | J22: 5 | K22: 5 | L22: 5 | M22: 5 | N22: 31 | O22: 20
A23: 11 | B23: 0 | C23: 6 | F23: 6 | H23: 5 | I23: 5 | J23: 5 | K23: 4 | L23: 5 | M23: 4 | N23: 28 | O23: 19
A24: 12 | B24: 4 | C24: 10 | F24: 6 | G24: 0 | H24: 5 | I24: 5 | J24: 5 | K24: 5 | L24: 5 | M24: 5 | N24: 36 | O24: 16
A25: 13 | B25: 2 | C25: 14 | D25: 3 | F25: 4 | H25: 5 | I25: 5 | J25: 5 | K25: 5 | L25: 5 | M25: 5 | N25: 35 | O25: 11
A26: 14 | B26: 2 | C26: 10 | D26: 4 | E26: 8 | F26: 4 | G26: 2 | H26: 5 | I26: 5 | J26: 5 | K26: 5 | L26: 5 | M26: 5 | N26: 39 | O26: 21
A27: 15 | B27: 0 | C27: 17 | D27: 3 | E27: 8 | F27: 10 | G27: 1 | H27: 5 | I27: 5 | J27: 5 | K27: 4 | L27: 5 | M27: 5 | N27: 42 | O27: 22
A28: 16 | B28: 4 | C28: 18 | D28: 4 | H28: 5 | I28: 5 | J28: 5 | K28: 5 | L28: 5 | M28: 5 | N28: 32 | O28: 11
A29: 17 | B29: 2 | C29: 6 | D29: 3 | E29: 2 | F29: 4 | H29: 5 | I29: 5 | J29: 5 | K29: 5 | L29: 5 | M29: 5 | N29: 16 | O29: 17
A30: 18 | B30: 0 | C30: 0 | E30: 8 | F30: 4 | H30: 5 | I30: 5 | J30: 5 | K30: 5 | L30: 5 | M30: 5 | N30: 12 | O30: 14
A31: 19 | B31: 0 | C31: 10 | D31: 3 | E31: 8 | F31: 4 | H31: 5 | I31: 5 | J31: 4 | K31: 5 | L31: 5 | M31: 5 | N31: 0 | O31: 14
A32: 20 | B32: 3 | C32: 4 | F32: 10 | G32: 2 | H32: 5 | I32: 5 | J32: 5 | K32: 5 | L32: 4 | M32: 5 | N32: 38 | O32: 18
A33: 21 | B33: 1 | C33: 6 | D33: 3 | F33: 2 | G33: 6 | H33: 5 | I33: 5 | J33: 5 | K33: 5 | L33: 5 | M33: 5 | N33: 13 | O33: 15
A34: 22 | B34: 0 | C34: 6 | D34: 4 | F34: 0 | G34: 4 | H34: 5 | I34: 5 | J34: 5 | K34: 5 | L34: 5 | M34: 5 | N34: 13 | O34: 15
A35: 23 | B35: 4 | C35: 6 | D35: 3 | F35: 0 | G35: 12 | H35: 5 | I35: 5 | J35: 5 | K35: 5 | L35: 4 | M35: 5 | N35: 35 | O35: 21
A36: 24 | B36: 1 | C36: 12 | D36: 1 | F36: 6 | G36: 12 | H36: 5 | I36: 5 | J36: 5 | K36: 5 | L36: 5 | M36: 4 | N36: 50 | O36: 22
A37: 25 | B37: 3 | C37: 18 | D37: 4 | F37: 6 | G37: 12 | H37: 5 | I37: 5 | J37: 5 | K37: 4 | L37: 5 | M37: 4 | N37: 16 | O37: 22
A38: 26 | B38: 2 | C38: 1 | F38: 4 | G38: 12 | H38: 5 | I38: 5 | J38: 5 | K38: 5 | L38: 5 | M38: 5 | N38: 28 | O38: 18
A39: 27 | B39: 0 | C39: 7 | G39: 12 | H39: 5 | I39: 5 | J39: 5 | K39: 5 | L39: 5 | M39: 5 | N39: 28 | O39: 22
A40: 28 | B40: 0 | C40: 0 | D40: 1 | F40: 4 | G40: 12 | H40: 5 | I40: 5 | J40: 5 | K40: 4 | L40: 4 | M40: 4 | N40: 31 | O40: 22
A41: 29 | B41: 0 | C41: 0 | F41: 2 | G41: 12 | H41: 3 | I41: 2 | J41: 2 | K41: 2 | L41: 2 | M41: 2 | N41: 28 | O41: 22
...

Sheet CO_Attainment
AM1: Subject:
AM2: IAA==(0.8*CT1+0.8*CT2+0.1*MPR+0.1*CES) | AX2: EAA | AY2: =(1*AI19) -> 2
A3: Department of Computer Engineering | AM3: Course: : Internal Assessment Attainment | AX3: IAA | AY3: =AS10 -> 2.6666667
A4: Academic Year-2022-23 | AM4: CO'S | AN4: CT1 | AO4: CT2 | AP4: MiroProject | AR4: CES | AS4: IAA | AT4: Final 60% IAA | AU4: EAA | AV4: Final 40% EAA | AW4: Final Attainment 100%
A5: Branch:- Computer Division – C,D,E Course- Applied Mathematics Course Code-22224 | AM5: 22224.1 | AN5: =AVERAGE(F19,G19,H19,I19,J19,O19) -> 3 | AP5: 3 | AR5: 3 | AS5: =(0.8*AN5+0.8*AO5+0.1*AP5+0.1*AR5) -> 3 | AT5: =0.6*AS5 -> 1.8 | AU5: 2 | AV5: =0.4*AU5 -> 0.8 | AW5: =AT5+AV5 -> 2.6
AM6: 22224.2 | AO6: =AVERAGE(T19,U19,Y19) -> 2.3333333 | AP6: 3 | AR6: 3 | AS6: =(0.8*AN6+0.8*AO6+0.1*AP6+0.1*AR6) -> 2.4666667 | AT6: =0.6*AS6 -> 1.48 | AU6: 2 | AV6: =0.4*AU6 -> 0.8 | AW6: =AT6+AV6 -> 2.28
AM7: 22224.3 | AO7: =AVERAGE(Q19,R19,S19,W19) -> 2.75 | AP7: 3 | AR7: 3 | AS7: =(0.8*AN7+0.8*AO7+0.1*AP7+0.1*AR7) -> 2.8 | AT7: =0.6*AS7 -> 1.68 | AU7: 2 | AV7: =0.4*AU7 -> 0.8 | AW7: =AT7+AV7 -> 2.48
A8: Attainment Sheet | AM8: 22224.4 | AO8: =AVERAGE(V19,X19,Z19) -> 2.3333333 | AP8: 3 | AR8: 3 | AS8: =(0.8*AN8+0.8*AO8+0.1*AP8+0.1*AR8) -> 2.4666667 | AT8: =0.6*AS8 -> 1.48 | AU8: 2 | AV8: =0.4*AU8 -> 0.8 | AW8: =AT8+AV8 -> 2.28
A9: CO Assessment sheet, 2022-23 | AB9: Micoproject | AD9: CES | AI9: ESE-Theory | AM9: 22224.5 | AN9: =AVERAGE(K19,L19,M19,N19) -> 2.5 | AP9: 3 | AR9: 3 | AS9: =(0.8*AN9+0.8*AO9+0.1*AP9+0.1*AR9) -> 2.6 | AT9: =0.6*AS9 -> 1.56 | AU9: 2 | AV9: =0.4*AU9 -> 0.8 | AW9: =AT9+AV9 -> 2.36
AR10: Average | AS10: =AVERAGE(AS5:AS9) -> 2.6666667
B11: Roll No. | C11: Enrollment No | D11: Name of Student | F11: CT-1 | Q11: CT-2
E12: Q | F12: Q1a | G12: Q1b | H12: Q.1(c) | I12: Q.1(d) | J12: Q.1(e) | K12: Q.1(f) | L12: Q2a | M12: Q2b | N12: Q2c | O12: Q2d | Q12: Q1a | R12: Q1b | S12: Q1c | T12: Q1d | U12: Q1e | V12: Q1f | W12: Q2a | X12: Q2b | Y12: Q2c | Z12: Q2d | AB12: All | AD12: CO1 | AE12: CO2 | AF12: CO3 | AG12: CO4 | AH12: CO5 | AI12: ALL | AL12: 3 | AM12: >60 | AN12: Almost Achieved
E13: CO | F13: 22224.1 | G13: 22224.1 | H13: 22224.1 | I13: 22224.1 | J13: 22224.1 | K13: 22224.5 | L13: 22224.5 | M13: 22224.5 | N13: 22224.5 | O13: 22224.1 | Q13: 22224.3 | R13: 22224.3 | S13: 22224.3 | T13: 22224.2 | U13: 22224.2 | V13: 22224.4 | W13: 22224.3 | X13: 22224.4 | Y13: 22224.2 | Z13: 22224.4 | AD13: Q1 | AE13: Q2 | AF13: Q3 | AG13: Q4 | AH13: Q5 | AL13: 2 | AM13: 40-60 | AN13: Moderately Achieved
E14: Marks | F14: 2 | G14: 2 | H14: 2 | I14: 2 | J14: 2 | K14: 2 | L14: 4 | M14: 4 | N14: 4 | O14: 4 | Q14: 2 | R14: 2 | S14: 2 | T14: 2 | U14: 2 | V14: 2 | W14: 4 | X14: 4 | Y14: 4 | Z14: 4 | AB14: 10 | AD14: 5 | AE14: 5 | AF14: 5 | AG14: 5 | AH14: 5 | AI14: 70 | AL14: 1 | AM14: <40 | AN14: Low Ahieved
E15: Threshold | F15: =ROUND(F14*0.5,0) -> 1 | G15: =ROUND(G14*0.5,0) -> 1 | H15: =ROUND(H14*0.5,0) -> 1 | I15: =ROUND(I14*0.5,0) -> 1 | J15: =ROUND(J14*0.5,0) -> 1 | K15: =ROUND(K14*0.5,0) -> 1 | L15: =ROUND(L14*0.5,0) -> 2 | M15: =ROUND(M14*0.5,0) -> 2 | ... O15: =ROUND(O14*0.5,0) -> 2 | Q15: =ROUND(Q14*0.5,0) -> 1 | R15: =ROUND(R14*0.5,0) -> 1 | S15: =ROUND(S14*0.5,0) -> 1 | T15: =ROUND(T14*0.5,0) -> 1 | U15: =ROUND(U14*0.5,0) -> 1 | V15: =ROUND(V14*0.5,0) -> 1 | W15: =ROUND(W14*0.5,0) -> 2 | X15: =ROUND(X14*0.5,0) -> 2 | ... Z15: =ROUND(Z14*0.5,0) -> 2 | AB15: =ROUND(AB14*0.5,0) -> 5 | AD15: =ROUND(AD14*0.5,0) -> 3 | AE15: =ROUND(AE14*0.5,0) -> 3 | AF15: =ROUND(AF14*0.5,0) -> 3 | AG15: =ROUND(AG14*0.5,0) -> 3 | AH15: =ROUND(AH14*0.5,0) -> 3 | AI15: =ROUND(AI14*0.5,0) -> 35
E16: No. of Students Appeared for CO | F16: =COUNTIF(F21:F227,">=0") -> 201 | G16: =COUNTIF(G21:G227,">=0") -> 182 | H16: =COUNTIF(H21:H227,">=0") -> 134 | I16: =COUNTIF(I21:I227,">=0") -> 133 | J16: =COUNTIF(J21:J227,">=0") -> 115 | K16: =COUNTIF(K21:K227,">=0") -> 122 | L16: =COUNTIF(L21:L227,">=0") -> 144 | M16: =COUNTIF(M21:M227,">=0") -> 141 | ... O16: =COUNTIF(O21:O227,">=0") -> 126 | Q16: =COUNTIF(Q21:Q227,">=0") -> 163 | R16: =COUNTIF(R21:R227,">=0") -> 133 | S16: =COUNTIF(S21:S227,">=0") -> 143 | T16: =COUNTIF(T21:T227,">=0") -> 101 | U16: =COUNTIF(U21:U227,">=0") -> 123 | V16: =COUNTIF(V21:V227,">=0") -> 131 | W16: =COUNTIF(W21:W227,">=0") -> 121 | X16: =COUNTIF(X21:X227,">=0") -> 102 | ... Z16: =COUNTIF(Z21:Z227,">=0") -> 74 | AB16: =COUNTIF(AB21:AB227,">=0") -> 206 | AD16: =COUNTIF(AD21:AD227,">=0") -> 206 | AE16: =COUNTIF(AE21:AE227,">=0") -> 206 | AF16: =COUNTIF(AF21:AF227,">=0") -> 206 | AG16: =COUNTIF(AG21:AG227,">=0") -> 206 | AH16: =COUNTIF(AH21:AH227,">=0") -> 206 | AI16: =COUNTIF(AI21:AI227,">=0") -> 206
E17: No. of student Score more than 40-% marks | F17: =COUNTIF((F21:F227),">=1") -> 193 | G17: =COUNTIF((G21:G227),">=1") -> 170 | H17: =COUNTIF((H21:H227),">=1") -> 111 | I17: =COUNTIF((I21:I227),">=1") -> 110 | J17: =COUNTIF((J21:J227),">=1") -> 95 | K17: =COUNTIF((K21:K227),">=1") -> 103 | L17: =COUNTIF((L21:L227),">=2") -> 73 | M17: =COUNTIF((M21:M227),">=2") -> 74 | N17: =COUNTIF((N21:N227),">=2") -> 92 | O17: =COUNTIF((O21:O227),">=2") -> 80 | Q17: =COUNTIF((Q21:Q227),">=1") -> 105 | R17: =COUNTIF((R21:R227),">=1") -> 79 | S17: =COUNTIF((S21:S227),">=1") -> 111 | T17: =COUNTIF((T21:T227),">=1") -> 39 | U17: =COUNTIF((U21:U227),">=1") -> 93 | V17: =COUNTIF((V21:V227),">=1") -> 113 | W17: =COUNTIF((W21:W227),">=2") -> 75 | X17: =COUNTIF((X21:X227),">=2") -> 56 | Y17: =COUNTIF((Y21:Y227),">=2") -> 77 | Z17: =COUNTIF((Z21:Z227),">=2") -> 38 | AB17: =COUNTIF((AB21:AB227),">=5") -> 205 | AD17: =COUNTIF((AD21:AD227),">=3") -> 195 | AE17: =COUNTIF((AE21:AE227),">=3") -> 179 | AF17: =COUNTIF((AF21:AF227),">=3") -> 194 | AG17: =COUNTIF((AG21:AG227),">=3") -> 192 | AH17: =COUNTIF((AH21:AH227),">=3") -> 196 | AI17: =COUNTIF((AI21:AI227),">=35") -> 82
E18: % of student score more than 40-% Marks | F18: =F17/F16*100 -> 96.0199 | G18: =G17/G16*100 -> 93.406593 | H18: =H17/H16*100 -> 82.835821 | I18: =I17/I16*100 -> 82.706767 | J18: =J17/J16*100 -> 82.608696 | K18: =K17/K16*100 -> 84.42623 | L18: =L17/L16*100 -> 50.694444 | M18: =M17/M16*100 -> 52.48227 | ... O18: =O17/O16*100 -> 63.492063 | Q18: =Q17/Q16*100 -> 64.417178 | R18: =R17/R16*100 -> 59.398496 | S18: =S17/S16*100 -> 77.622378 | T18: =T17/T16*100 -> 38.613861 | U18: =U17/U16*100 -> 75.609756 | V18: =V17/V16*100 -> 86.259542 | W18: =W17/W16*100 -> 61.983471 | X18: =X17/X16*100 -> 54.901961 | ... Z18: =Z17/Z16*100 -> 51.351351 | AB18: =AB17/AB16*100 -> 99.514563 | AD18: =AD17/AD16*100 -> 94.660194 | AE18: =AE17/AE16*100 -> 86.893204 | AF18: =AF17/AF16*100 -> 94.174757 | AG18: =AG17/AG16*100 -> 93.203883 | AH18: =AH17/AH16*100 -> 95.145631 | AI18: =AI17/AI16*100 -> 39.805825
E19: ATTAINMENT (DIRECT) | F19: 3 | G19: 3 | H19: 3 | I19: 3 | J19: 3 | K19: 3 | L19: 2 | M19: 2 | N19: 3 | O19: 3 | Q19: 3 | R19: 2 | S19: 3 | T19: 1 | U19: 3 | V19: 3 | W19: 3 | X19: 2 | Y19: 3 | Z19: 2 | AB19: 3 | AD19: 3 | AE19: 3 | AF19: 3 | AG19: 3 | AH19: 3 | AI19: 2
A21: 1 | B21: 1101 | C21: ENR001 | D21: STU001 | F21: 2 | G21: 2 | H21: 2 | I21: 2 | J21: 2 | K21: 2 | L21: 4 | M21: 4 | N21: 4 | O21: 4 | Q21: 2 | R21: 2 | S21: 2 | T21: 2 | U21: 2 | V21: 2 | W21: 4 | X21: 4 | Y21: 4 | Z21: 4 | AB21: 10 | AD21: 3 | AE21: 3 | AF21: 3 | AG21: 3 | AH21: 3 | AI21: 69
A22: 2 | B22: 1102 | C22: ENR002 | D22: STU002 | F22: 2 | G22: 2 | I22: 2 | J22: 1 | K22: 2 | L22: 4 | M22: 1 | N22: 4 | O22: 4 | R22: 2 | S22: 2 | U22: 2 | V22: 2 | W22: 4 | X22: 3 | Y22: 4 | Z22: 4 | AB22: 10 | AD22: 3 | AE22: 3 | AF22: 5 | AG22: 4 | AH22: 5 | AI22: 75
A23: 3 | B23: 1103 | C23: ENR003 | D23: STU003 | F23: 1 | G23: 2 | J23: 0 | K23: 2 | L23: 2 | M23: 2 | N23: 2 | Q23: 0 | R23: 0 | S23: 0 | V23: 1 | W23: 0 | X23: 0 | Y23: 0 | AB23: 8 | AD23: 4 | AE23: 4 | AF23: 5 | AG23: 5 | AH23: 5 | AI23: 27
A24: 4 | B24: 1104 | C24: ENR004 | D24: STU004 | F24: 2 | G24: 2 | H24: 2 | I24: 2 | J24: 2 | K24: 2 | M24: 4 | N24: 3 | O24: 4 | Q24: 2 | R24: 1 | S24: 1 | U24: 1 | V24: 2 | W24: 4 | X24: 3 | Y24: 4 | AB24: 9 | AD24: 5 | AE24: 4 | AF24: 5 | AG24: 4 | AH24: 5 | AI24: 55
A25: 5 | B25: 1105 | C25: ENR005 | D25: STU005 | F25: 2 | G25: 2 | H25: 1 | I25: 2 | J25: 2 | K25: 2 | M25: 4 | N25: 4 | O25: 4 | Q25: 2 | R25: 2 | S25: 2 | U25: 2 | W25: 4 | X25: 4 | Y25: 4 | AB25: 10 | AD25: 3 | AE25: 3 | AF25: 5 | AG25: 4 | AH25: 5 | AI25: 44
A26: 6 | B26: 1106 | C26: ENR006 | D26: STU006 | F26: 2 | G26: 2 | H26: 2 | I26: 2 | J26: 1 | L26: 4 | M26: 2 | N26: 4 | O26: 4 | R26: 2 | S26: 2 | T26: 2 | U26: 2 | V26: 2 | W26: 4 | X26: 4 | Y26: 4 | Z26: 4 | AB26: 10 | AD26: 5 | AE26: 5 | AF26: 5 | AG26: 5 | AH26: 5 | AI26: 86
A27: 7 | B27: 1107 | C27: ENR007 | D27: STU007 | F27: 2 | G27: 2 | H27: 2 | I27: 2 | J27: 1 | K27: 2 | M27: 2 | Q27: 0 | S27: 0 | T27: 0 | AB27: 8 | AD27: 3 | AE27: 3 | AF27: 5 | AG27: 4 | AH27: 5 | AI27: 22
A28: 8 | B28: 1108 | C28: ENR008 | D28: STU008 | F28: AB | G28: AB | H28: AB | I28: AB | J28: AB | K28: AB | L28: AB | M28: AB | N28: AB | O28: AB | Q28: AB | R28: AB | S28: AB | T28: AB | U28: AB | V28: AB | W28: AB | X28: AB | Y28: AB | Z28: AB | AB28: 2 | AD28: 5 | AE28: 5 | AF28: 5 | AG28: 5 | AH28: 5 | AI28: 2
A29: 9 | B29: 1109 | C29: ENR009 | D29: STU009 | F29: 2 | G29: 2 | H29: 2 | I29: 2 | K29: 2 | L29: 4 | N29: 3 | O29: 4 | Q29: 2 | R29: 2 | S29: 2 | T29: 1 | U29: 2 | V29: 2 | W29: 4 | X29: 4 | Y29: 4 | Z29: 4 | AB29: 10 | AD29: 3 | AE29: 3 | AF29: 5 | AG29: 4 | AH29: 5 | AI29: 63
A30: 10 | B30: 1110 | C30: ENR010 | D30: STU010 | F30: 2 | G30: 2 | H30: 2 | I30: 2 | J30: 1 | K30: 1 | L30: 4 | M30: 4 | N30: 4 | O30: 4 | Q30: 0 | S30: 1 | U30: 2 | V30: 2 | W30: 0 | X30: 1 | Y30: 1 | AB30: 8 | AD30: 3 | AE30: 3 | AF30: 5 | AG30: 4 | AH30: 5 | AI30: 53
A31: 11 | B31: 1111 | C31: ENR011 | D31: STU011 | F31: 2 | G31: 2 | H31: 2 | I31: 2 | J31: 2 | L31: 4 | M31: 4 | O31: 4 | Q31: 2 | R31: 2 | S31: 2 | T31: 2 | U31: 2 | V31: 2 | W31: 4 | X31: 4 | Y31: 4 | Z31: 3 | AB31: 10 | AD31: 3 | AE31: 1 | AF31: 3 | AG31: 1 | AH31: 5 | AI31: 84
A32: 12 | B32: 1112 | C32: ENR012 | D32: STU012 | F32: 1 | G32: 2 | H32: 1 | I32: 2 | J32: 1 | M32: 2 | O32: 4 | U32: 2 | V32: 1 | AB32: 6 | AD32: 2 | AE32: 4 | AF32: 2 | AG32: 5 | AH32: 3 | AI32: 42
A33: 13 | B33: 1113 | C33: ENR013 | D33: STU013 | F33: 2 | G33: 2 | J33: 2 | K33: 1 | L33: 4 | M33: 4 | N33: 1 | S33: 1 | T33: 0 | U33: 0 | V33: 2 | X33: 2 | Y33: 2 | Z33: 0 | AB33: 8 | AD33: 5 | AE33: 3 | AF33: 5 | AG33: 4 | AH33: 5 | AI33: 27
A34: 14 | B34: 1114 | C34: ENR014 | D34: STU014 | F34: 2 | G34: 2 | H34: 1 | I34: 1 | L34: 0 | M34: 1 | N34: 0 | Q34: 1 | S34: 0 | U34: 1 | V34: 1 | W34: 0 | X34: 0 | Z34: 0 | AB34: 7 | AD34: 4 | AE34: 3 | AF34: 3 | AG34: 3 | AH34: 4 | AI34: 16
A35: 15 | B35: 1115 | C35: ENR015 | D35: STU015 | F35: 1 | G35: 0 | J35: 1 | K35: 2 | M35: 4 | N35: 2 | R35: 0 | S35: 2 | U35: 0 | V35: 2 | W35: 0 | Z35: 0 | AB35: 6 | AD35: 5 | AE35: 3 | AF35: 5 | AG35: 5 | AH35: 5 | AI35: 16
A36: 16 | B36: 1116 | C36: ENR016 | D36: STU016 | F36: 2 | G36: 2 | H36: 2 | I36: 1 | L36: 4 | M36: 1 | N36: 4 | O36: 2 | Q36: 2 | R36: 2 | S36: 1 | T36: 1 | U36: 1 | W36: 2 | Y36: 4 | Z36: 0 | AB36: 9 | AD36: 3 | AE36: 3 | AF36: 5 | AG36: 4 | AH36: 5 | AI36: 40
A37: 17 | B37: 1117 | C37: ENR017 | D37: STU017 | F37: 1 | H37: 2 | J37: 1 | K37: 1 | L37: 1 | M37: 2 | O37: 0 | Q37: 2 | U37: 1 | V37: 1 | W37: 4 | X37: 0 | Z37: 2 | AB37: 8 | AD37: 3 | AE37: 3 | AF37: 5 | AG37: 4 | AH37: 5 | AI37: 35
A38: 18 | B38: 1118 | C38: ENR018 | D38: STU018 | F38: 1 | G38: 1 | H38: 1 | I38: 2 | K38: 2 | L38: 1 | M38: 2 | N38: 3 | S38: 2 | V38: 2 | X38: 4 | Z38: 4 | AB38: 7 | AD38: 5 | AE38: 5 | AF38: 5 | AG38: 3 | AH38: 5 | AI38: 47
A39: 19 | B39: 1119 | C39: ENR019 | D39: STU019 | G39: 2 | I39: 2 | J39: 2 | K39: 2 | M39: 4 | N39: 4 | O39: 4 | S39: 2 | T39: 0 | U39: 1 | V39: 2 | X39: 0 | Y39: 3 | Z39: 4 | AB39: 9 | AD39: 4 | AE39: 3 | AF39: 5 | AG39: 4 | AH39: 5 | AI39: 53
A40: 20 | B40: 1120 | C40: ENR020 | D40: STU020 | F40: 2 | G40: 1 | H40: 1 | I40: 1 | K40: 2 | L40: 4 | M40: 2 | O40: 3 | Q40: 0 | R40: 1 | T40: 1 | V40: 1 | W40: 1 | X40: 0 | Y40: 3 | AB40: 7 | AD40: 2 | AE40: 5 | AF40: 3 | AG40: 4 | AH40: 2 | AI40: 38
A41: 21 | B41: 1121 | C41: ENR021 | D41: STU021 | F41: 2 | G41: 1 | H41: 1 | K41: 2 | L41: 4 | M41: 2 | O41: 3 | R41: 1 | T41: 1 | U41: 1 | V41: 1 | W41: 1 | X41: 4 | Y41: 3 | AB41: 8 | AD41: 5 | AE41: 3 | AF41: 4 | AG41: 5 | AH41: 4 | AI41: 32
...

Sheet Action_Taken 
A1: A.Y | B1: 2022-23 | D1: Class and Div | F1: FY | G1: C,D,E | H1: Faculty | I1: Ms. S.S.Patil
A2: course code | C2: 22224 | D2: Course | E2: AMI
A3: CO-PO/PSO Mapping
A5: CO | B5: PO | I5: PSO | L5: CO'S | M5: CT1 | N5: CT2 | O5: MiroProject | P5: CAS | Q5: CES | R5: IAA | S5: Final 60% IAA | T5: EAA | U5: Final 40% EAA | V5: Final Attainment 100%
B6: 1 | C6: 2 | D6: 3 | E6: 4 | F6: 5 | G6: 6 | H6: 7 | I6: 1 | J6: 2 | L6: 22224.1 | M6: 3 | O6: 3 | Q6: 3 | R6: 3 | S6: 1.8 | T6: 2 | U6: 0.8 | V6: 2.6
A7: 22224.1 | B7: 2 | C7: 2 | D7: 2 | E7: 2 | G7: 2 | H7: 1 | I7: 1 | L7: 22224.2 | N7: 2.3333333 | O7: 3 | Q7: 3 | R7: 2.4666667 | S7: 1.48 | T7: 2 | U7: 0.8 | V7: 2.28
A8: 22224.2 | B8: 1.6666667 | C8: 1.6666667 | F8: 1.6666667 | H8: 1 | I8: 1 | L8: 22224.3 | N8: 2.75 | O8: 3 | Q8: 3 | R8: 2.8 | S8: 1.68 | T8: 2 | U8: 0.8 | V8: 2.48
A9: 22224.3 | B9: 1.3333333 | C9: 1.3333333 | F9: 1.3333333 | H9: 1 | I9: 1 | L9: 22224.4 | N9: 2.3333333 | O9: 3 | Q9: 3 | R9: 2.4666667 | S9: 1.48 | T9: 2 | U9: 0.8 | V9: 2.28
A10: 22224.4 | B10: 1.3333333 | C10: 1.3333333 | D10: 1.3333333 | E10: 1.3333333 | F10: 1.3333333 | G10: 1.3333333 | H10: 1 | I10: 1 | L10: 22224.5 | M10: 2.5 | O10: 3 | Q10: 3 | R10: 2.6 | S10: 1.56 | T10: 2 | U10: 0.8 | V10: 2.36
A11: 22224.5 | B11: 1.6666667 | C11: 1.6666667 | D11: 1.6666667 | E11: 1.6666667 | F11: 1.6666667 | G11: 1.3333333 | H11: 1 | I11: 1
B13: =IF(SUM(B7:B11)=0,"-",AVERAGE(B7:B11)) -> 1.6 | C13: =IF(SUM(C7:C11)=0,"-",AVERAGE(C7:C11)) -> 1.6 | D13: =IF(SUM(D7:D11)=0,"-",AVERAGE(D7:D11)) -> 1.6666667 | E13: =IF(SUM(E7:E11)=0,"-",AVERAGE(E7:E11)) -> 1.6666667 | F13: =IF(SUM(F7:F11)=0,"-",AVERAGE(F7:F11)) -> 1.5 | G13: =IF(SUM(G7:G11)=0,"-",AVERAGE(G7:G11)) -> 1.5555556 | H13: =IF(SUM(H7:H11)=0,"-",AVERAGE(H7:H11)) -> 1 | I13: =IF(SUM(I7:I11)=0,"-",AVERAGE(I7:I11)) -> 1
A15: CO-PO Attained matrix
A16: CO | B16: PO1 | C16: PO2 | D16: PO3 | E16: PO4 | F16: PO5 | G16: PO6 | H16: PO7 | I16: PSO1 | J16: PSO2
A17: 22224.1 | B17: =(B7*$V$6)/3 -> 1.7333333 | C17: =(C7*$V$6)/3 -> 1.7333333 | E17: =(E7*$V$6)/3 -> 1.7333333 | G17: =(G7*$V$6)/3 -> 1.7333333 | H17: =(H7*$V$6)/3 -> 0.86666667 | I17: =(I7*$V$6)/3 -> 0.86666667
A18: 22224.2 | B18: =(B8*$V$7)/3 -> 1.2666667 | C18: =(C8*$V$7)/3 -> 1.2666667 | F18: =(F8*$V$7)/3 -> 1.2666667 | G18: =(G8*$V$7)/3 -> 0 | H18: =(H8*$V$7)/3 -> 0.76 | I18: =(I8*$V$7)/3 -> 0.76
A19: 22224.3 | B19: =(B9*$V$8)/3 -> 1.1022222 | H19: =(H9*$V$8)/3 -> 0.82666667 | I19: =(I9*$V$8)/3 -> 0.82666667
A20: 22224.4 | B20: =(B10*$V$9)/3 -> 1.0133333 | C20: =(C10*$V$9)/3 -> 1.0133333 | D20: =(D10*$V$9)/3 -> 1.0133333 | E20: =(E10*$V$9)/3 -> 1.0133333 | G20: =(G10*$V$9)/3 -> 1.0133333 | H20: =(H10*$V$9)/3 -> 0.76 | I20: =(I10*$V$9)/3 -> 0.76
A21: 22224.5 | B21: =(B11*$V$10)/3 -> 1.3111111 | C21: =(C11*$V$10)/3 -> 1.3111111 | D21: =(D11*$V$10)/3 -> 1.3111111 | E21: =(E11*$V$10)/3 -> 1.3111111 | F21: =(F11*$V$10)/3 -> 1.3111111 | G21: =(G11*$V$10)/3 -> 1.0488889 | H21: =(H11*$V$10)/3 -> 0.78666667 | I21: =(I11*$V$10)/3 -> 0.78666667
A22: Attainment (Direct) | B22: =AVERAGE(B17:B21) -> 1.2853333 | C22: =AVERAGE(C17:C21) -> 1.3311111 | D22: =AVERAGE(D17:D21) -> 1.1622222 | E22: =AVERAGE(E17:E21) -> 1.3525926 | F22: =AVERAGE(F17:F21) -> 1.2888889 | G22: =AVERAGE(G17:G21) -> 0.94888889 | H22: =AVERAGE(H17:H21) -> 0.8 | I22: =AVERAGE(I17:I21) -> 0.8
A24: CO/PO | B24: PO1 | C24: PO2 | D24: PO3 | E24: PO4 | F24: PO5 | G24: PO6 | H24: PO7 | I24: PSO1 | J24: PSO2
A25: Target | B25: =B13 -> 1.6 | C25: =C13 -> 1.6 | D25: =D13 -> 1.6666667 | E25: =E13 -> 1.6666667 | F25: =F13 -> 1.5 | G25: =G13 -> 1.5555556 | H25: =H13 -> 1 | I25: =I13 -> 1
A26: Attained | B26: =B22 -> 1.2853333 | C26: =C22 -> 1.3311111 | D26: =D22 -> 1.1622222 | E26: =E22 -> 1.3525926 | F26: =F22 -> 1.2888889 | G26: =G22 -> 0.94888889 | H26: =H22 -> 0.8 | I26: =I22 -> 0.8
A27: % Attainment | B27: =(B26/B25)*100 -> 80.333333 | C27: =(C26/C25)*100 -> 83.194444 | D27: =(D26/D25)*100 -> 69.733333 | E27: =(E26/E25)*100 -> 81.155556 | F27: =(F26/F25)*100 -> 85.925926 | G27: =(G26/G25)*100 -> 61 | H27: =(H26/H25)*100 -> 80 | I27: =(I26/I25)*100 -> 80
A35: Attainment Level
A36: Highly Achived | C36: If % of attainment is greater than 80%
A37: Moderately achieved | C37: If % of attainment is in between than 60 to80%
A38: poorly achieved | C38: If % of attainment is in between than 30 to 59.99%
A39: Not Achieved | C39: If % of attainment is less than 30 %
A44: Observations & Action Planned
A45: PO | B45: % Attainment 2022-23 | D45: Level | H45: Action to be taken in 2023-24
A46: PO1 | B46: =B27 -> 80.333333 | D46: Highly Achived | H46: 1) The videos related to difficult points prepared by msbte were sent to students to clear the concepts . 2)Chapterwise Assignments questions provied for getting familler . 3) In Academic year i.e. 2020-21due to panedemic examination was conducted in online mode where 50% weightage was for objective and 50% weightage for subjective evaluation. It helped to raise the result of this coursewith the type of question and type of answer to be written for examination. 4) Assessment of 22103.2 based on practise only so planned to take more practice on that part. 5) Planned to continue same activity based learning for difficult chapter to raise students mark.
A47: PO2 | B47: =C27 -> 83.194444 | D47: Highly Achived
A48: PO3 | B48: =D27 -> 69.733333 | D48: Moderately achieved
A49: PO4 | B49: =E27 -> 81.155556 | D49: Highly Achived
A50: PO5 | B50: =F27 -> 85.925926 | D50: Highly Achived
A51: PO6 | B51: =G27 -> 61 | D51: Moderately achieved
A52: PO7 | B52: =H27 -> 80 | D52: Moderately achieved
A53: PSO1 | B53: =I27 -> 80 | D53: Moderately achieved
A54: PSO2

Sheet Dashboard
A1: Academic Performance & CO-PO Attainment Dashboard
A4: TOTAL STUDENTS | D4: NUMBER OF COs | G4: AVERAGE CO ATTAINMENT
A5: =COUNTA(CO_Attainment!D21:D227) -> 207 | D5: =COUNTA(CO_Attainment!AD12:AH12) -> 5 | G5: =AVERAGE(CO_Attainment!AW5:AW9) -> 2.4

Sheet Sheet2

Sheet ATTAINMENT
A1: =RAW!B2 -> -
A2: Assessment Tool | B2: MT | E2: ET | I2: CE
B3: =RAW!B4 -> C403.1 | C3: =RAW!C4 -> C403.2 | D3: =RAW!D4 -> C403.3 | E3: =RAW!E4 -> C403.4 | F3: =RAW!F4 -> C403.5 | G3: =RAW!G4 -> C403.6 | I3: =RAW!H4 -> #REF! | J3: =RAW!I4 -> C403.2 | K3: =RAW!J4 -> C403.3 | L3: =RAW!K4 -> C403.4 | M3: =RAW!L4 -> C403.5 | N3: =RAW!M4 -> C403.6
A4: Attainement | B4: =RAW!B12 -> 0 | C4: =RAW!C12 -> 1 | D4: =RAW!D12 -> 3 | E4: =RAW!E12 -> 3 | F4: =RAW!F12 -> 3 | G4: =RAW!G12 -> 1 | I4: =RAW!H12 -> 3 | J4: =RAW!I12 -> 3 | K4: =RAW!J12 -> 3 | L4: =RAW!K12 -> 3 | M4: =RAW!L12 -> 3 | N4: =RAW!M12 -> 3
J6: TW | L6: UE
J7: ALL CO | L7: =RAW!N4 -> ALL CO
J8: =RAW!O12 -> 3 | L8: =RAW!N12 -> 1
A11: CO | B11: INTERNAL(60%) | M11: Internal Assessment Attainment IAA | N11: External (40%) | P11: External Assessment EA | Q11: Final CO Attainment
B12: CT1 | C12: CT2 | J12: MP | K12: TW | L12: CES | N12: ESE-PR | O12: ESE-TH
A13: Weightages for tools | B13: 0.15 | C13: 0.15 | J13: 0.1 | K13: 0.15 | L13: 0.05 | M13: =SUM(B13:L13) -> 0.6 | N13: 0.4 | P13: =SUM(N13:O13) -> 0.4 | Q13: =M13+P13 -> 1
A14: =CO_PO_Mapping!U8 -> C403.1 | B14: =B4 -> 0 | K14: =J8 -> 3 | L14: =I4 -> 3 | M14: =((AVERAGE(B14*$B$13))+(K14*$K$13)+(L14*$L$13)) -> 0.6 | N14: =L8 -> 1 | P14: =(N14*$N$13)+(O14*O13) -> 0.4 | Q14: =M14+P14 -> 1
A15: =CO_PO_Mapping!U9 -> C403.2 | B15: =C4 -> 1 | K15: =J8 -> 3 | L15: =J4 -> 3 | M15: =((AVERAGE(B15*$B$13))+(K15*$K$13)+(L15*$L$13)) -> 0.75 | N15: 1 | P15: =(N15*$N$13)+(O15*O14) -> 0.4 | Q15: =M15+P15 -> 1.15
A16: =CO_PO_Mapping!U10 -> C403.3 | B16: =D4 -> 3 | K16: =J8 -> 3 | L16: =K4 -> 3 | M16: =((AVERAGE(B16*$B$13))+(K16*$K$13)+(L16*$L$13)) -> 1.05 | N16: 1 | P16: =(N16*$N$13)+(O16*O15) -> 0.4 | Q16: =M16+P16 -> 1.45
A17: =CO_PO_Mapping!U11 -> C403.4 | C17: =E4 -> 3 | K17: =J8 -> 3 | L17: =L4 -> 3 | M17: =((AVERAGE(C17*$C$13))+(K17*$K$13)+(L17*$L$13)) -> 1.05 | N17: 1 | P17: =(N17*$N$13)+(O17*O16) -> 0.4 | Q17: =M17+P17 -> 1.45
A18: =CO_PO_Mapping!U12 -> C403.5 | C18: =F4 -> 3 | K18: =J8 -> 3 | L18: =M4 -> 3 | M18: =((AVERAGE(C18*$C$13))+(K18*$K$13)+(L18*$L$13)) -> 1.05 | N18: 1 | P18: =(N18*$N$13)+(O18*O17) -> 0.4 | Q18: =M18+P18 -> 1.45
A19: =CO_PO_Mapping!U13 -> C403.6 | C19: =G4 -> 1 | K19: =J8 -> 3 | L19: =N4 -> 3 | M19: =((AVERAGE(C19*$C$13))+(K19*$K$13)+(L19*$L$13)) -> 0.75 | N19: 1 | P19: =(N19*$N$13)+(O19*O18) -> 0.4 | Q19: =M19+P19 -> 1.15
A21: Final CO-PO Attainment for Course
A22: CO | B22: PO | N22: PSO
B23: 1 | C23: 2 | D23: 3 | E23: 4 | F23: 5 | G23: 6 | H23: 7 | I23: 8 | J23: 9 | K23: 10 | L23: 11 | M23: 12 | N23: 1 | O23: 2
A24: =CO_PO_Mapping!#REF! -> #REF! | B24: =IF(CO_PO_Mapping!V8="-","-",(CO_PO_Mapping!V8/3)*ATTAINMENT!$Q$14) -> 0 | C24: =IF(CO_PO_Mapping!W8="-","-",(CO_PO_Mapping!W8/3)*ATTAINMENT!$Q$14) -> 0
A25: =CO_PO_Mapping!U20 -> C403.2 | B25: =IF(CO_PO_Mapping!V9="-","-",(CO_PO_Mapping!V9/3)*ATTAINMENT!$Q$15) -> 0 | C25: =IF(CO_PO_Mapping!W9="-","-",(CO_PO_Mapping!W9/3)*ATTAINMENT!$Q$15) -> 0 | D25: =IF(CO_PO_Mapping!X9="-","-",(CO_PO_Mapping!X9/3)*ATTAINMENT!$Q$15) -> 0 | E25: =IF(CO_PO_Mapping!AA9="-","-",(CO_PO_Mapping!AA9/3)*ATTAINMENT!$Q$15) -> 0 | F25: =IF(CO_PO_Mapping!AB9="-","-",(CO_PO_Mapping!AB9/3)*ATTAINMENT!$Q$15) -> 0 | G25: =IF(CO_PO_Mapping!AC9="-","-",(CO_PO_Mapping!AC9/3)*ATTAINMENT!$Q$15) -> 0 | J25: =IF(CO_PO_Mapping!AF9="-","-",(CO_PO_Mapping!AF9/3)*ATTAINMENT!$Q$15) -> 0 | K25: =IF(CO_PO_Mapping!AG9="-","-",(CO_PO_Mapping!AG9/3)*ATTAINMENT!$Q$15) -> 0 | N25: =IF(CO_PO_Mapping!AJ9="-","-",(CO_PO_Mapping!AJ9/3)*ATTAINMENT!$Q$15) -> 0 | O25: =IF(CO_PO_Mapping!AK9="-","-",(CO_PO_Mapping!AK9/3)*ATTAINMENT!$Q$15) -> 0
A26: =CO_PO_Mapping!U21 -> C403.3 | B26: =IF(CO_PO_Mapping!V10="-","-",(CO_PO_Mapping!V10/3)*ATTAINMENT!$Q$16) -> 0 | C26: =IF(CO_PO_Mapping!W10="-","-",(CO_PO_Mapping!W10/3)*ATTAINMENT!$Q$16) -> 0 | D26: =IF(CO_PO_Mapping!X10="-","-",(CO_PO_Mapping!X10/3)*ATTAINMENT!$Q$16) -> 0 | E26: =IF(CO_PO_Mapping!AA10="-","-",(CO_PO_Mapping!AA10/3)*ATTAINMENT!$Q$16) -> 0 | F26: =IF(CO_PO_Mapping!AB10="-","-",(CO_PO_Mapping!AB10/3)*ATTAINMENT!$Q$16) -> 0 | G26: =IF(CO_PO_Mapping!AC10="-","-",(CO_PO_Mapping!AC10/3)*ATTAINMENT!$Q$16) -> 0 | J26: =IF(CO_PO_Mapping!AF10="-","-",(CO_PO_Mapping!AF10/3)*ATTAINMENT!$Q$16) -> 0 | K26: =IF(CO_PO_Mapping!AG10="-","-",(CO_PO_Mapping!AG10/3)*ATTAINMENT!$Q$16) -> 0 | N26: =IF(CO_PO_Mapping!AJ10="-","-",(CO_PO_Mapping!AJ10/3)*ATTAINMENT!$Q$16) -> 0 | O26: =IF(CO_PO_Mapping!AK10="-","-",(CO_PO_Mapping!AK10/3)*ATTAINMENT!$Q$16) -> 0
A27: =CO_PO_Mapping!U22 -> C403.4 | B27: =IF(CO_PO_Mapping!V11="-","-",(CO_PO_Mapping!V11/3)*ATTAINMENT!$Q$17) -> 0 | C27: =IF(CO_PO_Mapping!W11="-","-",(CO_PO_Mapping!W11/3)*ATTAINMENT!$Q$17) -> 0 | D27: =IF(CO_PO_Mapping!X11="-","-",(CO_PO_Mapping!X11/3)*ATTAINMENT!$Q$17) -> 0 | E27: =IF(CO_PO_Mapping!AA11="-","-",(CO_PO_Mapping!AA11/3)*ATTAINMENT!$Q$17) -> 0 | F27: =IF(CO_PO_Mapping!AB11="-","-",(CO_PO_Mapping!AB11/3)*ATTAINMENT!$Q$17) -> 0 | G27: =IF(CO_PO_Mapping!AC11="-","-",(CO_PO_Mapping!AC11/3)*ATTAINMENT!$Q$17) -> 0 | J27: =IF(CO_PO_Mapping!AF11="-","-",(CO_PO_Mapping!AF11/3)*ATTAINMENT!$Q$17) -> 0 | K27: =IF(CO_PO_Mapping!AG11="-","-",(CO_PO_Mapping!AG11/3)*ATTAINMENT!$Q$17) -> 0 | N27: =IF(CO_PO_Mapping!AJ11="-","-",(CO_PO_Mapping!AJ11/3)*ATTAINMENT!$Q$17) -> 0 | O27: =IF(CO_PO_Mapping!AK11="-","-",(CO_PO_Mapping!AK11/3)*ATTAINMENT!$Q$17) -> 0
A28: =CO_PO_Mapping!U23 -> C403.5 | B28: =IF(CO_PO_Mapping!V12="-","-",(CO_PO_Mapping!V12/3)*ATTAINMENT!$Q$18) -> 0 | C28: =IF(CO_PO_Mapping!W12="-","-",(CO_PO_Mapping!W12/3)*ATTAINMENT!$Q$18) -> 0 | D28: =IF(CO_PO_Mapping!X12="-","-",(CO_PO_Mapping!X12/3)*ATTAINMENT!$Q$18) -> 0 | E28: =IF(CO_PO_Mapping!AA12="-","-",(CO_PO_Mapping!AA12/3)*ATTAINMENT!$Q$18) -> 0 | F28: =IF(CO_PO_Mapping!AB12="-","-",(CO_PO_Mapping!AB12/3)*ATTAINMENT!$Q$18) -> 0 | G28: =IF(CO_PO_Mapping!AC12="-","-",(CO_PO_Mapping!AC12/3)*ATTAINMENT!$Q$18) -> 0 | J28: =IF(CO_PO_Mapping!AF12="-","-",(CO_PO_Mapping!AF12/3)*ATTAINMENT!$Q$18) -> 0 | K28: =IF(CO_PO_Mapping!AG12="-","-",(CO_PO_Mapping!AG12/3)*ATTAINMENT!$Q$18) -> 0 | N28: =IF(CO_PO_Mapping!AJ12="-","-",(CO_PO_Mapping!AJ12/3)*ATTAINMENT!$Q$18) -> 0 | O28: =IF(CO_PO_Mapping!AK12="-","-",(CO_PO_Mapping!AK12/3)*ATTAINMENT!$Q$18) -> 0
A29: =CO_PO_Mapping!U24 -> C403.6 | B29: =IF(CO_PO_Mapping!V13="-","-",(CO_PO_Mapping!V13/3)*ATTAINMENT!$Q$19) -> 0 | C29: =IF(CO_PO_Mapping!W13="-","-",(CO_PO_Mapping!W13/3)*ATTAINMENT!$Q$19) -> 0 | D29: =IF(CO_PO_Mapping!X13="-","-",(CO_PO_Mapping!X13/3)*ATTAINMENT!$Q$19) -> 0 | E29: =IF(CO_PO_Mapping!AA13="-","-",(CO_PO_Mapping!AA13/3)*ATTAINMENT!$Q$19) -> 0 | F29: =IF(CO_PO_Mapping!AB13="-","-",(CO_PO_Mapping!AB13/3)*ATTAINMENT!$Q$19) -> 0 | G29: =IF(CO_PO_Mapping!AC13="-","-",(CO_PO_Mapping!AC13/3)*ATTAINMENT!$Q$19) -> 0 | J29: =IF(CO_PO_Mapping!AF13="-","-",(CO_PO_Mapping!AF13/3)*ATTAINMENT!$Q$19) -> 0 | K29: =IF(CO_PO_Mapping!AG13="-","-",(CO_PO_Mapping!AG13/3)*ATTAINMENT!$Q$19) -> 0 | N29: =IF(CO_PO_Mapping!AJ13="-","-",(CO_PO_Mapping!AJ13/3)*ATTAINMENT!$Q$19) -> 0 | O29: =IF(CO_PO_Mapping!AK13="-","-",(CO_PO_Mapping!AK13/3)*ATTAINMENT!$Q$19) -> 0
A30: =CO_PO_Mapping!U14 -> 0 | B30: =IF(SUM(B24:B29)=0,"-",AVERAGE(B24:B29)) -> - | C30: =IF(SUM(C24:C29)=0,"-",AVERAGE(C24:C29)) -> - | D30: =IF(SUM(D24:D29)=0,"-",AVERAGE(D24:D29)) -> - | E30: =IF(SUM(E24:E29)=0,"-",AVERAGE(E24:E29)) -> - | F30: =IF(SUM(F24:F29)=0,"-",AVERAGE(F24:F29)) -> - | G30: =IF(SUM(G24:G29)=0,"-",AVERAGE(G24:G29)) -> - | H30: =IF(SUM(H24:H29)=0,"-",AVERAGE(H24:H29)) -> - | I30: =IF(SUM(I24:I29)=0,"-",AVERAGE(I24:I29)) -> - | ... O30: =IF(SUM(O24:O29)=0,"-",AVERAGE(O24:O29)) -> -
F48: Final CO-PO Attainment for Course
F65: Final CO-PSO Attainment for Course

Sheet Observation and action taken
B1: Target and Attainment
B2: CO/PO | D2: PO1 | E2: PO2 | F2: PO3 | G2: PO4 | H2: PO5 | I2: PO6 | J2: PO7 | K2: PO8 | L2: PO9 | M2: PO10 | N2: PO11 | O2: PO12 | P2: PSO1 | Q2: PSO2
B3: Target | C3: C403
B4: Attained | C4: C403
B5: % Attainment | D5: =D4/D3*100 -> #DIV/0! | E5: =E4/E3*100 -> #DIV/0! | F5: =F4/F3*100 -> #DIV/0! | G5: =G4/G3*100 -> #DIV/0! | H5: =H4/H3*100 -> #DIV/0! | L5: =L4/L3*100 -> #DIV/0! | M5: =M4/M3*100 -> #DIV/0! | P5: =P4/P3*100 -> #DIV/0! | Q5: =Q4/Q3*100 -> #DIV/0!
B7: Impact of action Taken (Target and Attainment AY 2022-23)
B9: CO/PO | D9: PO1 | E9: PO2 | F9: PO3 | G9: PO4 | H9: PO5 | I9: PO6 | J9: PO7 | K9: PO8 | L9: PO9 | M9: PO10 | N9: PO11 | O9: PO12 | P9: PSO1 | Q9: PSO2
B10: Target | C10: C403 | D10: 2 | E10: 2 | F10: 2 | G10: 2 | H10: 1.4 | I10: 1.2 | J10: - | K10: - | L10: 1.4 | M10: 1.4 | N10: - | O10: - | P10: 1 | Q10: 1.2
B11: Attained | C11: C403 | D11: 1.0333333 | E11: 1.0333333 | F11: 1.0666667 | G11: 1.0666667 | H11: 0.75666667 | I11: 0.64 | J11: - | K11: - | L11: 0.75666667 | M11: 0.75666667 | N11: - | O11: - | P11: 0.54333333 | Q11: 0.64
B12: % Attainment | D12: =D11/D10*100 -> 51.666667 | E12: =E11/E10*100 -> 51.666667 | F12: =F11/F10*100 -> 53.333333 | G12: =G11/G10*100 -> 53.333333 | H12: =H11/H10*100 -> 54.047619 | I12: =I11/I10*100 -> 53.333333 | L12: =L11/L10*100 -> 54.047619 | M12: =M11/M10*100 -> 54.047619 | P12: =P11/P10*100 -> 54.333333 | Q12: =Q11/Q10*100 -> 53.333333
A14: Attainment Level
A15: Highly Achived | C15: If % of attainment is greater than 83.33%
A16: Moderately achieved | C16: If % of attainment is in between than 60 to 83.33%
A17: poorly achieved | C17: If % of attainment is in between than 30 to 59.99%
A18: Not Achieved | C18: If % of attainment is less than 30 %
A20: Status of attainment 2022-23
A21: PO | B21: % Attainment | D21: Level | F21: Observation | L21: action to be taken
A22: PO1 | B22: =D12 -> 51.666667 | D22: Poorly Achieved | F22: Students were lacking understand and apply the basic concepts of FEA to solve engineering problems. | L22: This is the last batch of CBCS pattern. So no action taken is planned.
A23: PO2 | B23: =E12 -> 51.666667 | D23: Poorly Achieved | F23: Students were not able to solve the problems of 1D, plane stress, plain strain,axisymmetric and heat transfer problems using principles of mathematics.
A24: PO3 | B24: =F12 -> 53.333333 | D24: Poorly Achieved | F24: Students were not able to design solutions for complex problems.
A25: PO4 | B25: =G12 -> 53.333333 | D25: Poorly Achieved | F25: Students were not able to analyze and interpret the data.
A26: PO5 | B26: =H12 -> 54.047619 | D26: Poorly Achieved | F26: Students were unable to use ANSYS software to model and analyse the engineering problem on 1D (stepped bar,beam), 2D(plane stress and plain strain) & heat transfer problems.
A27: PO6 | B27: =I12 -> 53.333333 | D27: Poorly Achieved
A28: PO9 | B28: =L12 -> 54.047619 | D28: Poorly Achieved | F28: Students were unable to solve the problems individually. Students were unable to use ANSYS software to perform the analysis individually.
A29: PO10 | B29: =M12 -> 54.047619 | D29: Poorly Achieved | F29: Students were unable to communicate effectively.
A30: PSO1 | B30: =P12 -> 54.333333 | D30: Poorly Achieved | F30: Student were unable to apply the knowledge in ENGG. science while performing the structural analysis.
A31: PSO2 | B31: =Q12 -> 53.333333 | D31: Poorly Achieved | F31: Student were unable to apply the knowledge in thermal science while performing the heat transfer analysis of piston.
B36: Course Teacher | H36: Program coordinator | N36: H.o.D.
